-------------------------
    Entidad/Proceso: authorizationhold
    Hora de inicio: 2023-07-10 11:41:17.189815-05:00
    Hora final: 2023-07-10 11:47:32.037027-05:00
    Query: 
    Estado: OK
    

    -------------------------
    Entidad/Proceso: cardreference
    Hora de inicio: 2023-07-10 11:47:32.182963-05:00
    Hora final: 2023-07-10 11:52:05.757416-05:00
    Query: 
    Estado: OK
    

    -------------------------
    Entidad/Proceso: client
    Hora de inicio: 2023-07-10 11:52:05.874479-05:00
    Hora final: 2023-07-10 12:07:44.228687-05:00
    Query: 
    Estado: error
    

    Error: Traceback (most recent call last):
  File "/home/spark/.local/lib/python3.7/site-packages/awswrangler/_databases.py", line 265, in read_sql_query
    timestamp_as_object=timestamp_as_object,
  File "/home/spark/.local/lib/python3.7/site-packages/awswrangler/_databases.py", line 225, in _fetch_all_results
    cursor.execute(*cursor_args)
  File "/home/spark/.local/lib/python3.7/site-packages/pymysql/cursors.py", line 148, in execute
    result = self._query(query)
  File "/home/spark/.local/lib/python3.7/site-packages/pymysql/cursors.py", line 310, in _query
    conn.query(q)
  File "/home/spark/.local/lib/python3.7/site-packages/pymysql/connections.py", line 548, in query
    self._affected_rows = self._read_query_result(unbuffered=unbuffered)
  File "/home/spark/.local/lib/python3.7/site-packages/pymysql/connections.py", line 775, in _read_query_result
    result.read()
  File "/home/spark/.local/lib/python3.7/site-packages/pymysql/connections.py", line 1156, in read
    first_packet = self.connection._read_packet()
  File "/home/spark/.local/lib/python3.7/site-packages/pymysql/connections.py", line 692, in _read_packet
    packet_header = self._read_bytes(4)
  File "/home/spark/.local/lib/python3.7/site-packages/pymysql/connections.py", line 749, in _read_bytes
    CR.CR_SERVER_LOST, "Lost connection to MySQL server during query"
pymysql.err.OperationalError: (2013, 'Lost connection to MySQL server during query')

During handling of the above exception, another exception occurred:

Traceback (most recent call last):
  File "/tmp/write_mambu_tables.py", line 603, in process_write_mambu
    max_val = get_max_value(table, bookmark_str, jobglue)
  File "/tmp/write_mambu_tables.py", line 118, in get_max_value
    tdf = wr.mysql.read_sql_query(query, con=con)
  File "/home/spark/.local/lib/python3.7/site-packages/awswrangler/mysql.py", line 236, in read_sql_query
    timestamp_as_object=timestamp_as_object,
  File "/home/spark/.local/lib/python3.7/site-packages/awswrangler/_databases.py", line 278, in read_sql_query
    con.rollback()
  File "/home/spark/.local/lib/python3.7/site-packages/pymysql/connections.py", line 479, in rollback
    self._execute_command(COMMAND.COM_QUERY, "ROLLBACK")
  File "/home/spark/.local/lib/python3.7/site-packages/pymysql/connections.py", line 793, in _execute_command
    raise err.InterfaceError(0, "")
pymysql.err.InterfaceError: (0, '')
 
